Workbook

Sheet Sheet4
D2: Kozma | E2: Luiza
D3: Alphatec x Petrobras | E3: Vitória
D4: Precatórios Valecard | E4: AP | N4: =COUNTIFS(Pipe!G:G,Sheet4!$O4) -> 245 | O4: 2024
D5: TANAC | E5: Mauad | N5: =COUNTIFS(Pipe!G:G,Sheet4!$O5) -> 372 | O5: 2025
D6: Transpetro | E6: Luiza | N6: =COUNTIFS(Pipe!G:G,Sheet4!$O6)/7*12 -> 457.71429 | O6: 2026
D7: FIDC BLUE II | E7: Todos
D8: Espólio Maria Nubia e PBR | E8: Vitória
D9: Pizzato x União Federal / IBAMA | E9: Vitória
D10: Humberto x Braskem | E10: Vitória
D11: Sussumo e Itimura vs Incra | E11: Vitória
D12: Petro-Alpha x Petrobras | E12: Vitória
D13: Jose Teixeira x INCRA | E13: Vitória

Sheet Pipe
D3: Planilha de Controle do Pipeline - Special Situations | K3: =75*60% -> 45 | P3: =900+800+800+700+500 -> 3700
E4: Não | F4: Em análise | G4: Concluído | H4: On Hold | I4: Total | M4: =120/30% -> 400
D5: Oportunidades Apresentadas | E5: =COUNTIF($N:$N,E4) -> 736 | F5: =COUNTIF($N:$N,F4) -> 38 | G5: 23 | H5: =COUNTIF($N:$N,H4) -> 100 | I5: =+E5+F5+H5 -> 874 | K5: =82*6.2 -> 508.4 | R5: =295/7 -> 42.142857
C8: # | D8: Tipo de Operação | E8: Nome | F8: Data Entrada | G8: year | H8: Contato | I8: Tipo de Contato | J8: Descrição da Oportunidade | K8: Status da Operação | L8: Valor (R$ mm) | M8: Responsável | N8: Decisão | O8: Data de Saída | P8: Feedback
C9: 1 | D9: Precatórios | E9: Precatórios do Estado do RN | F9: 45303 | G9: =+YEAR(F9) -> 2024 | H9: Thiago Cordeiro - DBV Capital | J9: 156 - Cumprimento de Sentença | K9: - | N9: Não | P9: Valor baixo e estado do RN está bem atrasado em sua fila de pagamentos (pagando fila de 2006)
C10: =+C9+1 -> 2 | D10: Precatórios | E10: Precatórios do Estado do MT | F10: 45307 | G10: =+YEAR(F10) -> 2024 | H10: Thiago Cordeiro - DBV Capital | J10: 39 - Não alimentar - Desapropriações | K10: - | N10: Não | P10: Tese conhecida do Instituto do Açúcar e do Álcool - IAA; em nossa análise, a tese está frequentemente exposta a viradas jurisprudenciais, trazendo riscos adicionais para os créditos
C11: =+C10+1 -> 3 | D11: Precatórios | E11: Precatórios do Estado do PR | F11: 45315 | G11: =+YEAR(F11) -> 2024 | H11: Emanuel Cavalcanti - Convexa Investimentos | J11: - | K11: - | N11: Não | P11: PR está bem atrasado em sua fila de pagamentos, atualmente ainda quitando precatórios do orçamento 2005/2006, o que tende a alongar o prazo para recebimento da oportunidade enviada, visto que estão inscritos no orçamento 2016
C12: =+C11+1 -> 4 | D12: Precatórios | E12: Precatórios da Camargo Correa | F12: 45306 | G12: =+YEAR(F12) -> 2024 | H12: Marco Andre Alencar | J12: 39 - Não alimentar - Desapropriações | K12: 26/01 - Sinalizamos que conseguiríamos ~25% do valor, com earn-out. Marco ficou de retornar, porém, com essas condições, há grandes chances de não seguirem com a negociação | N12: Não | P12: 23/02 - Com a possibilidade de acordo dos precatorios, nossa proposta não é atrativa para o vendedor do precatório
C13: =+C12+1 -> 5 | D13: Precatórios | E13: Precatórios do Estado do PA | F13: 45314 | G13: =+YEAR(F13) -> 2024 | H13: Stellar Capital | I13: Broker | J13: Desapropriação Propriedade Rural no Pará | K13: 02/02 - Jorio solicitou um call para passarmos pela oportunidade. 02/02 - Luiza vai responder ao email do Jorio 05/02 - Aguardando ligação do Jorio | N13: Não | P13: 23/02 - Prazo longo e risco elevado
C14: =+C13+1 -> 6 | D14: Crédito para Operação | E14: Grupo ASN | F14: 45302 | G14: =+YEAR(F14) -> 2024 | H14: Paulo Viola | J14: Empresa de cultivo de café, laranja e banana e nutrição animal, dívida de 68mm | K14: 01/01 - Realizamos reunião com Celso, para explicar que as dívidas baratas nao devem ser quitadas integralmente, entendemos que deve ser uma entrada para entao renegociá-las. Para nosso empréstimo, precisamos de novos imoveis como garantia, Celso nos retornará se ha garantias disponíveis e se há intenção de monetizá-las Falar com o Alberto sobre a operação recebida, entender com o Alberto se seria uma operação imobiliária 23/02 - Cobrar o Paulo sobre as fazendas herdadas e puxar para fazer um novo call com o Alberto e o Celso (26/02) 28/02 - Não enviaram novas infos de imoveis, somente o contrato de venda de laranja (em análise) 04/03 - Reunião com Celso e Paulo para entender a proposta indicativa que receberam às 10h30 05/03. 05/03 - Enviaram um range de valores para a taxa da operação proposta. Precisamos definir como seguir aqui. | N14: Não | P14: Não queremos tomar o risco de fazer um sale leaseback de um ativo que no momento pode ser não operacional mas que esta nos planos do Alberto. Vamos marcar um call. Call agendado para segunda feira 14h. Confirmar
C15: =+C14+1 -> 7 | D15: DIP para RJ | E15: Grupo OHAEC | F15: 45306 | G15: =+YEAR(F15) -> 2024 | H15: Andreia Alonso | J15: Grupo OHAEC, são donos do colegio Helio Alonso (Meier) e Faculdade Facha, em RJ desde abril de 2022 | K15: 02/02 - Realizamos o call com as socias do Grupo e novas solicitações de informações foram feitas 08/02 - Enviaram dados financeiros, projeções e avaliação dos imoveis de São Gonçalo e Meier (R$ 2,3mm e R$ 2mm) 23/02 - Pendente de devolutiva para o time de Facha, oportunidade em análise 26/02 - Entender com a JGP FA se a família tem mais garantia do que o que foi enviado, só com essas garantias não vamos aprovar a operação 05/03 - Pendente de feedback para Cia indicando que caso nao haja mais imoveis disponíveis não é possivel fazer o empréstimo | L15: 10 | N15: Não | P15: 14/03 - Oportunidade declinada no momento devido a falta de collateral para um potencial empréstimo
C16: =+C15+1 -> 8 | D16: DIP para RJ | E16: Grupo JS | F16: 45315 | G16: =+YEAR(F16) -> 2024 | H16: Fernando Galvão | J16: Financimanento para o Grupo JS (em RJ) dar de entrada no parcelamento dos impostos junto à PGFN | K16: - | N16: Não | P16: TIR que acenamos aos nossos investidores em Roadshow recente supera com alguma margem a TIR no caso base (que nos pareceu mais provável também) da operação. (CDI+12%)
C17: =+C16+1 -> 9 | D17: Precatórios Federais | E17: Yolanda e Elide | F17: 45314 | G17: =+YEAR(F17) -> 2024 | H17: JGP FA | J17: Yolanda e Elide - Ambos são decorrentes de desapropriação e atualmente também consta autorização no inventário da Yolanda | K17: 26/01 - Enviamos para William que estaríamos dispostos a desembolsar até 65% do valor de face 31/01 - Solicitamos os autos dos inventários da Yolanda e Elide 06/02 - Enviado o Espólio da Yolanda e Precatórios expedidos pelo TRF 2 28/02 - Pendente de confirmação se há algum representante para negociação do precatório para Elide. Para sra. Yolanda precisamos do formal de partilha para endereçar a melhor maneira de conduzir a potencial aquisição dos direitos creditórios | N17: Não | P17: Não aceitaram o preço proposto (pgto de 65% do PU - incluindo o broker)
C18: =+C17+1 -> 10 | D18: Crédito para CapEx | E18: Horizonte Minerals | F18: 45315 | G18: =+YEAR(F18) -> 2024 | H18: Moelis | J18: Financiamento para finalizar as obras da primeira planta de exploração de Niquel | K18: 15/01 - Fizemos uma primeira reunião com o CEO e COO e time Moelis para apresentação da oportunidade 30/01 - Recebemos acesso ao Data Room 22/02 - Participamos de uma apresentação do conselho sobre o novo BP. Moelis abriu oportunidade de marcar um call para tirarmos dúvida 22/02 - Sinalizaram TIR de 15% em USD 28/02 - Ainda não atualizaram o VDR com a estrutura de capital alvo da Companhia 08/03 - Definir a data para reuniao de apresentação de capital structure | N18: Não | P18: Baixa chance de montarmos essa operação por ser uma greenfield de niquel
C19: =+C18+1 -> 11 | D19: Crédito para Operação | E19: Grupo SMH | F19: 45489 | G19: =+YEAR(F19) -> 2024 | H19: JGP FA | J19: Hospital em Petropolis com numeros operacionais negativos, solicitando captação para melhoria operacional | K19: Íntegra ficou de analisar sobre uma potencial gestão interina na Companhia, pendente de resposta 23/02 - Chris vai conversar com o Lassance sobre a oportunidade 01/03 - Tivemos um call com o Vidal da IFA, para gestão interina na Cia. Time da JGP FA vai falar com o board da Cia para entender a situação atual da empresa 08/03 - Cobrar fernando de uma atualização sobre o ponto acima 22/03 - Pendente de resposta do Fernando (ainda sem resposta) 29/04 - Contrataram a Deloitte para gestão interina | M19: Christopher | N19: Não | P19: 29/04 - Contrataram a Deloitte para gestão interina
C20: =+C19+1 -> 12 | D20: Crédito para Operação | E20: Inplac | F20: - | G20: =+YEAR(F20) -> #VALUE! | H20: JGP FA | J20: Indústria de produtos plásticos que saiu da RJ em 2021 mas ainda está com necessidade de caixa | K20: Dez/23 - Solicitamos informações sobre a Cia que ainda não foram enviadas 30/01 - Fizemos um FUP sobre o envio das infos, nos enviará no inicio da semana (05/02) 23/02 - Entender se a empresa já pagou os credores da RJ e entender pq as dívidas tributárias ficaram em aberto. A empresa está operacional? Pode entrar em RJ novamente? 04/03 - Aguardar a transação tributária e entender se a cia pode entrar em RJ novamente 15/03 - Vamos ligar para a Cia diretamente 01/04 - Principal acionista mostrou interesse em dar como garantia as ações do Costao e tb vender o ativo - Pendente de feedback o William (FA) após a reunião com a Empresa. 08/04 - Esperar o mandato da FA, as informações da dívida tributária, budget 2024 e entender se as garantias do Costão entrarão na potencial transação | M20: Mollica | N20: On Hold
C21: =+C20+1 -> 13 | D21: DIP/Equity para RJ | E21: OSX | F21: 45320 | G21: =+YEAR(F21) -> 2024 | H21: Henrique (JGP) | J21: Montante requerido sera para usado para recomprar dívidas das companhias e converter dívida em equity | K21: 30/01 - Recebemos o material, porem a transação envolve equity e um valuation que não traduz a realidade da empresas. Pendente de feedback 23/02 - Mollica vai passar o feedback para o responsável da OSX | N21: Não | P21: Entendemos não ser o perfil do fundo de Special sits devido alguns pontos: (i) Operação envolvendo equity; (ii) Valuation descolado do que entendemos ser o valor justo para a empresa (Mkt cap atual R$ 17mm x valor apresentado no InfoMemo R$ 700mm)
C22: =+C21+1 -> 14 | D22: Precatório Federal | E22: José Cardoso | F22: 45322 | G22: =+YEAR(F22) -> 2024 | H22: Gregory Pagot | J22: 39 - Não alimentar - Desapropriações | K22: 31/01 - Entender se esse precatório federal seria para o orçamento de 2024 15/03 - Vamos responder ao email do Gregory | M22: Hugo | N22: Não
C23: =+C22+1 -> 15 | D23: Crédito para Pgto do Bond | E23: Andrade Gutierrez | F23: 45322 | G23: =+YEAR(F23) -> 2024 | H23: QMS Capital | J23: Companhia esta buscando um new money para poder quitar o bond com vct em 2029 e cupom de 9% | K23: 02/01 - Oportunidade em análise Vamos agendar uma reunião com Palmier para entendermos a estrutura da Transação 08/02 - Enviaram as infos solicitadas, estamos modelando para analisar o crédito da Cia 09/02 - Reunião com Palmier e Galapagos para definir os termos da potencial transação 19/02 - Reuniao com todos os times para apresentarmos os termos e condições do TS, pendente de retorno da AG 22/02 - A Companhia está pendente de enviar as projeções e o 2023FY - devem enviar ainda essa semana (04/03) 18/03 - Andrade ganhou licitação para obras da refinaria Abreu de 3.9bi | L23: 150 | M23: Christopher | N23: Não
C24: =+C23+1 -> 16 | D24: Crédito | E24: Dock Brasil | F24: 45366 | G24: =+YEAR(F24) -> 2024 | H24: JGP FA | K24: 15/03 - Time da FA até dia 22/03 deve nos enviar o modelo e InfoMemo para analisarmos a oportunidade, até 27/03. 01/04 - Time da FA esta com modelagem pronta mas ainda pendente dos acionistas darem OK nos materiais 08/04- fizemos um call para repassar os materiais, vao ajustar o modelo e nos enviarão 17/04 - Enviaram o modelo 29/04 - Vamos fazer um call com o francis para discutir o modelo e nos enviarão as notas explicativas de 2023 até sexta 06/05 - Notas explicativas serão enviadas até 07/05 31/05 - time FA pediu ajuste na proposta 10/06 - Cobrar time FA sobre a reunião com TRG | L24: =19*5 -> 95 | M24: Mollica / Christopher | N24: On Hold
C25: =+C24+1 -> 17 | D25: Precatório Federal | E25: Ouricuri | F25: 45322 | G25: =+YEAR(F25) -> 2024 | H25: Gregory Pagot | J25: 10604 - Desapropriação por Interesse Social para Reforma Agrária/Art 184 | K25: 02/02 - Em análise (Obs: Valores elevados). 02/02 - Enviamos o questionamento sobre o motivo pelo qual a Jive esta vendendo 16/02 - Respondeu que enviou a oportunidade para a Jive também, porém afirmou que não era da Jive | N25: Não | P25: Muitos cessionários e não entendemos quem é o cedente
C26: =+C25+1 -> 18 | D26: Precatórios | E26: Precatórios do Estado do RJ - Solstad Offshore | F26: 45323 | G26: =+YEAR(F26) -> 2024 | H26: Thiago Cordeiro - DBV Capital | J26: Procedimento Comum - Icms- Outros / Imposto Sobre Circulação de Mercadorias / Impostos; Antecipação de Tutela E/ou Obrigação de Fazer Ou Não Fazer Ou Dar | K26: 01/02 - Em Análise. Os cedentes vão vender tudo e avaliam proposta acima de 45% 02/02 - Solicitamos uma nova proposta dado a possibilidade de acordo com os estados 22/02 - Respondeu que propostas em torno de 40% serão analisadas 28/02 - Declinaram propostas de 42%, vamos seguir? 04/03 - Pendente de responder o Thiago, declinando a oportunidade | N26: Não
C27: =+C26+1 -> 19 | D27: Crédito para Operação | E27: Turbi | F27: 45329 | G27: =+YEAR(F27) -> 2024 | H27: ARC Capital | J27: Novo dinheiro para compra das preferenciais da ARC | K27: 08/02 - Recebemos acesso ao Data room. Oportunidade declinada | N27: Não | P27: No caso dos fundos Special Sits avaliamos que a operação não nos atende no quesito de IRR (CDI +12%), e quanto aos fundos de dívida convencional já estamos bastante alocados em papéis de rental não cabendo mais exposição ao setor
C28: =+C27+1 -> 20 | D28: CRA ou CRI | E28: St.Marche | F28: 45329 | G28: =+YEAR(F28) -> 2024 | H28: Orama IB | J28: R$ 100 milhões com 24 meses de carência de principal, prazo de 5 anos e CDI + 5%. Passaram o caso com a Gabriela e Muller, mas pela estrutura de capital da cia (PL virado e ainda bem alavancada) preferiram não avançar | K28: 09/02 - Em análise 20/02 - Fizemos um call para entender a operação, porém a Companhia não possui ativos reais para garantias. Vamos negar? | N28: Não | P28: Entendemos não ser o perfil de Special Sits, seria um caso de capital solution (necessidade de captação de equity). Entendemos que a operação envolve equity e não conseguimos viabilizar agora, caso mude a estrutura do deal, pedimos que nos avisem por favor
C29: =+C28+1 -> 21 | D29: Crédito para Operação | E29: Losinox | F29: 45330 | G29: =+YEAR(F29) -> 2024 | H29: Heartman House | J29: Companhia precisa de empréstimo de R$ 30mm para Kgiro para compra de matéria prima. Além disso, precisa de R$ 5mm no CP para suprir necessidade de caixa | K29: 09/02 - Pendente envio de informação 22/02 - Realizamos um call para entendermos melhor a operação e enviamos um info request com solicitações adicionais 29/02 - Responderam parcialmente o info request, pendente do detalhamento da dívida 04/03 - Falar com o William sobre a renovação do aluguel de Ribeirao Pires 05/03 - Pendente de renegociação do contrato com a Aperam e entender o apetite deles para um pre pagamento da dívida (R$ 6.2mm) e liberação da hipoteca 15/03 - Enviamos uma mensagem com bullets dos principais pontos de uma potencial proposta de financiamento 28/03 - Estamos aguardando atualização do William sobre a renovação do contrato de aluguel com a Aperam e a possivel quitação do emprestimo da Losinox com a Aperam. | L29: 6.5 | M29: Luiza | N29: Não
C30: =+C29+1 -> 22 | D30: Crédito para Operação | E30: Armco | G30: =+YEAR(F30) -> 1900 | H30: JGP FA | J30: Principais players no mercado brasileiro de produtos de metais planos, atuando especificamente nos segmentos de laminados a frio e sistemas de embalagem | K30: 23/02 - Cobrar do Gabriel Nobrega da FA 01/03 - Matheus (FA) irá nos enviar as infos 04/03- Ligar par ao Gabrie para entednder melhor a operação 11/03 - Solicitamos infos adicionais 14/03 - Informaram que estão com exclusividade com outra casa, no momento está em stand-by 24/06 - Focal, advisor, enviou o material de Roadshow para o Mollica, ficou de analisar para entender se seguiremos 01/07 - Vamos negar devido a estrategia de aumentar o PL com a doação de imoveis, a uma valor que nao entendemos se traduz a realidade | M30: Christopher | N30: Não | P30: 02/07 - Negamos novamente por nao fzer sentido para o SS
C31: =+C30+1 -> 23 | D31: Compra de Carteira de Crédito | E31: Comexport | G31: =+YEAR(F31) -> 1900 | H31: Leonardo Campos Melo | I31: Advogado | K31: 23/02 - Luiza esta analisando a Carteira de vencidos - 04/03 - Há um crédito para ser melhor analisado, pendente de baixar o processo 08/03 - Luiza vai falar com o leonardo campos melo 15/03 - Luiza vai falar com o leonardo campos melo | M31: Luiza | N31: Não | P31: 01/04 - Operação não faz sentido para o fundo de SS
C32: =+C31+1 -> 24 | D32: Oportunidade de Crédito estressado | E32: Hotel Trump | G32: =+YEAR(F32) -> 1900 | H32: JGP FA | J32: Hotel em RJ | K32: 23/02 - Pendente do envio de informações pelo time JGP FA 23/02 - Baixar o processo para entender o FIP por trás do hotel Fernando Kunzel vai marcar um call com o Michel para entendermos melhor do case Mollica vai falar com alguma construtora para entender a oportunidade 07/03 - Call com a Cyrela, irão verificar alguns pontos: (i) se a debenture foi comprada; (ii) possibilidade da conversão de hotel para residencial; (iii) capacidade do imovel para retrofit 19/03 - Cyrela afirmou que a area construida do hotel não pode ser convertida de hotel para residencial | N32: Não | P32: As debentures foram compradas e não entrariamos comprando cota de FIP
C33: =+C32+1 -> 25 | D33: Oportunidade de Crédito estressado | E33: Frigorífico Rainha | F33: 45337 | G33: =+YEAR(F33) -> 2024 | H33: Vela Capital | J33: Oportunidade de crédito estressado para o Frigorífico Rainha no Paraná que está em RJ | K33: Em análise. Enviaram informações financeiras, pendente do envio da apresentação da Companhia - solicitado 21/02 07/03- Solicitamos identificarem se os fornecedores são rastreaveis ou não 13/03 - Enviaram as informações sobre a rastreabilidade dos fornecedores, estamos preparando um q&a para um call na semana que vem. 19/03- Iniciamos as analises e solicitamos mais informações (não temos clareza sobre as possíveis garantias dessa operação). Além disso, sugeriram uma redução no cheque para R$ 15mm 20/03 - Enviamos perguntas preliminares para o time da Vela Capital, pendente de resposta 26/06 - Enviaram as respostas de algumas perguntas que fizemos em Março/Abril 08/07 - Vamos negar a oportunidade | L33: 50 | M33: Christopher | N33: Não | P33: i) empresa com histórico de EBITDA negativo; ii) não temos conforto com operações no setor de frigoríficos; e iii) garantias não chegam a 100% do empréstimo, além de grande parte ser operacional.
C34: =+C33+1 -> 26 | D34: Precatório Federal | E34: Belém - Desapropriação | F34: 45344 | G34: =+YEAR(F34) -> 2024 | H34: Raphael Martins (Souto Correa) | J34: Desapropriações | K34: Através de uma análise inicial (ajustar por selic) entendemos que o % máximo do PU seria 60%. | M34: Luiza | N34: Não | P34: Declinado pelo cedente. Valor abaixo do esperado
C35: =+C34+1 -> 27 | D35: Precatório Federal | E35: Marcia Cristina | F35: 45338 | G35: =+YEAR(F35) -> 2024 | H35: Gregory Pagot | J35: Não Alimentar | K35: 15/02 - Recebemos a oportunidade do precatório federal em Brasilia de R$ 34mm, precisa ser analisado. Luiza pediu a ligação do Gregory 05/03 - Gregory enviou um email perguntando sobre o precatorio | M35: Luiza | N35: Não | P35: Ativo com muitos fundos e bem enrolado
C36: =+C35+1 -> 28 | D36: Crédito para Operação | E36: OBDI | F36: 45337 | G36: =+YEAR(F36) -> 2024 | H36: JGP FA | J36: A Companhia está buscando R$30mm em um novo empréstimo para garantir um potencial contrato com a Petrobras e ter caixa para novos contratos | K36: 15/02 - Em análise 26/02 - fizemos um call com o time FA para tirarmos duvidas preliminares 28/02 - Enviaram as condições do contrato com a Petrobras, porém pendente de enviar a relação dos imóveis que podem ser dados como garantia 05/03 - Conseguiram o contrato com a Petro e vao pegar um empréstimo com um banco. Pendente de devolutiva de respostas 14/03 - Locadoras tem perdas milionárias com queda de seminovo, isso impacta diretamente o business da OBDI 21/03- solução seria disponibilizar uma linha de credito que estaria disponível caso a empresa ganhe uma licitação, porem isso dificilmente seria aprovado em comite. Estariamos disponibilizando um credito sem contrapartida de receita em um primeiro momento, alem de prejudicar a rentabilidade | L36: 30 | M36: Christopher | N36: Não | P36: 01/04 - solução seria disponibilizar uma linha de credito que estaria disponível caso a empresa ganhe uma licitação, porem isso dificilmente seria aprovado em comite. Estariamos disponibilizando um credito sem contrapartida de receita em um primeiro momento, alem de prejudicar a rentabilidade
C37: =+C36+1 -> 29 | D37: Pré-precatório | E37: Data Traffic e DNIT | F37: 45337 | G37: =+YEAR(F37) -> 2024 | H37: Vicente Barros (Amavic) | J37: - | K37: 14/03 - Fechamos o racional de precificação, pendente de alinhar o % do vf a ser proposto. Há um outro player que ja colocou a proposta mas ainda não é algo que estão buscando. 15/03 - No dia 18/03 vamos nos atualizar para entender se avançou a negociação 22/03 - Agendar reunião com Vicente Barros para entender a evolução das negociações 22/04 - Reunião com potenciais investidores para a captação do fundo monotematico para esse investimento 26/04 - Primeira parte da transação (R$ 5mm) foi liquidada | L37: 147 | M37: Christopher e Hugo | N37: Concluído
C38: =+C37+1 -> 30 | D38: Refinanciamento da Dívida | E38: HI Plataform | F38: 45338 | G38: =+YEAR(F38) -> 2024 | H38: ExFin Advisory | J38: Refinanciamento de dívida e investimentos em expansão: Investimento em produto e desenvolvimento e máquina de vendas | K38: 26/03 - Liguei para a ExFin, unica garantia oferecida é de recebiveis da operação, a principio nao ha mais imoveis e a cia esta a mercado tentando captar dívida, estão vendo ~CDI+6% 01/04 - Caso nao voltem com as respostas das garantias e taxas vamos passar a oportunidade com o time de FA e então declinar | L38: 20 | M38: Christopher | N38: não | P38: 29/04 - Declinamos pois não tinha collateral suficiente (sem imoveis) e esperavam uma taxa mto baixa, ainda não era case de SS.
C39: =+C38+1 -> 31 | D39: Credito para RJ | E39: Terra Forte | F39: 45342 | G39: =+YEAR(F39) -> 2024 | H39: Alvarez & Marsal | J39: Crédito de R$ 25-30mm para pagar credores em atraso e capital de giro para a companhia | K39: 21/02 - Recebemos as informações e fizemos o primeiro call para tirarmos dúvidas com a A&M. 22/02 - Enviaram o modelo e estamos analisando 23/02 - Vamos ajustar o NDA enviado por eles | L39: 30 | M39: Christopher | N39: Não | P39: 01/03 - Entendemos que a companhia não possui capacidade de pagamento do empréstimo devido ao tamanho da safra e o custo de plantio para a próxima safra, além de poucas garantias disponíveis (ativos alienados ao BTG)
C40: =+C39+1 -> 32 | D40: Credito para RJ | E40: Elisa Agro | F40: 45343 | G40: =+YEAR(F40) -> 2024 | H40: Alvarez & Marsal | J40: Crédito de R$ 65 mm para plantio de algodão | K40: 21/02 - Recebemos as informações e fizemos o primeiro call para tirarmos dúvidas com a A&M. 22/02 -Pendente assinatura do NDA 23/02 - Vamos alinhar internamente 29/02 - Pendente do envio de novas solicitações 08/03 - Pendente de análise do Muller 18/03 - oportunidade negada | L40: 48.5 | M40: Christopher | N40: Não | P40: Oportunidade declinada devido: (I) a falta de previsibilidade da negociação do CRA e M&A; (II) O custo de financiamento para a operação de algodão nos pareceu caro quando comparado a margem media do algodão. (iii) Além do risco da safra
C41: =+C40+1 -> 33 | D41: Capital Solution | E41: Armazem do Grão | F41: 45342 | G41: =+YEAR(F41) -> 2024 | H41: JGP FA | J41: Hoje, o grupo totaliza 12 unidades entre Petrópolis, Teresópolis e Rio de Janeiro, e faturam mais de R$ 350 milhões. O efeito da pandemia do Covid-19, em conjunto com os investimentos feitos em 2020, deixou a cia com uma grande necessidade de caixa. Com isso, tomaram empréstimos que desequilibraram muito sua estrutura de capital | K41: 21/02 - Recebemos as informações do time JGP FA (Em análise) 04/03 - Pendente as informações de 2023 e entender a relação dos imóveis disponíveis 08/03 - Confirmar com o Fernando sobre a relação com Catalunha (PE) 15/03 - Alinhar o case com o Fernando na semana do dia 18/03 28/03 - FA recebeu os numeros de 2023 e irão nos enviar na semana que vem. Além disso, a Catalunha colocou uma proposta de deb. conversivel mas foi negado pelos acionistas 08/04 - Ainda não enviaram os números de 2023, vão enviar até 10/04 | M41: Mollica/Christopher | N41: On Hold
C42: =+C41+1 -> 34 | D42: Credito para RJ | E42: Brasfio | F42: 45345 | G42: =+YEAR(F42) -> 2024 | H42: Guilherme Sertorio | J42: Necessidade de captação de R$ 10mm, garantia de um imovel (não é da recuperanda) de R$ 25mm | K42: 04/03 - Sertorio enviará a informação. Estão descumprindo o plano, pendente de envio da matrícula do imóvel no MT. 08/03 - Luiza vai cobrar do Sertorio | M42: Luiza | N42: Não
C43: =+C42+1 -> 35 | E43: Odebrecht | G43: =+YEAR(F43) -> 1900 | H43: Lucas Cive | I43: Empresário / Executivo | J43: OBD quer vender creditos contra a prefeitura do RJ R$ 360mm | K43: Luiza marcará um call para entender melhor do crédito Em análise, porém dificilmente seguiremos para uma proposta 08/03 e 15/03 - Vamo conversar internamente sobre um possivel litigation finance 01/04 - estão revalidando nosso NDA e informações dos imóveis, vamos tentar fazer uma operação estruturada com 2 imóveis. 08/04 - estamos cobrando o NDA 15/04- Pendente de recebimento de informações | M43: Luiza | N43: não | P43: Não houve devolutiva do Lucas (CFO da OBD)
C44: =+C43+1 -> 36 | D44: Credito para Empresa | E44: Laticinios Damare | G44: =+YEAR(F44) -> 1900 | H44: Paulo Viola | J44: - | K44: 26/02 - Oportunidade enviada pelo Paulo Viola (em análise) 15/03 - Preparar um q&a inicial para entender se vamos seguir olhando ou não 19/03 - solicitamos ao viola que nos envie a relação de garantias que estão disponíveis para collateralizar o empréstimo | L44: 120 | M44: Christopher | N44: Não | P44: 25/03 - Oportunidade declinada devido: (i) somente 1 garantia com valor de laudo de R$ 50mm, sendo o emprestimo de 120mm; (ii) Do valor total de empréstimo, 70mm estavam negociados com a SICOOB, com a garantia operacional
...

Sheet Originadores
F2: Casos Trazidos
C3: # | D3: Originador | E3: Tipo de Originador | F3: 2024 | G3: =+F3+1 -> 2025 | H3: =+G3+1 -> 2026
C4: 1 | D4: 18IB | E4: Boutique | F4: =COUNTIFS(Pipe!$H:$H,Originadores!$D4,Pipe!$G:$G,Originadores!F$3) -> 0 | G4: =COUNTIFS(Pipe!$H:$H,Originadores!$D4,Pipe!$G:$G,Originadores!G$3) -> 1 | H4: =COUNTIFS(Pipe!$H:$H,Originadores!$D4,Pipe!$G:$G,Originadores!H$3) -> 0
C5: =+C4+1 -> 2 | D5: 3A Investimentos | E5: Broker | F5: =COUNTIFS(Pipe!$H:$H,Originadores!$D5,Pipe!$G:$G,Originadores!F$3) -> 1 | G5: =COUNTIFS(Pipe!$H:$H,Originadores!$D5,Pipe!$G:$G,Originadores!G$3) -> 0 | H5: =COUNTIFS(Pipe!$H:$H,Originadores!$D5,Pipe!$G:$G,Originadores!H$3) -> 0
C6: =+C5+1 -> 3 | D6: Acacio | E6: Broker | F6: =COUNTIFS(Pipe!$H:$H,Originadores!$D6,Pipe!$G:$G,Originadores!F$3) -> 1 | G6: =COUNTIFS(Pipe!$H:$H,Originadores!$D6,Pipe!$G:$G,Originadores!G$3) -> 0 | H6: =COUNTIFS(Pipe!$H:$H,Originadores!$D6,Pipe!$G:$G,Originadores!H$3) -> 0
C7: =+C6+1 -> 4 | D7: Aeté | E7: Advisor | F7: =COUNTIFS(Pipe!$H:$H,Originadores!$D7,Pipe!$G:$G,Originadores!F$3) -> 0 | G7: =COUNTIFS(Pipe!$H:$H,Originadores!$D7,Pipe!$G:$G,Originadores!G$3) -> 1 | H7: =COUNTIFS(Pipe!$H:$H,Originadores!$D7,Pipe!$G:$G,Originadores!H$3) -> 0
C8: =+C7+1 -> 5 | D8: Adriane Bueno | E8: Broker | F8: =COUNTIFS(Pipe!$H:$H,Originadores!$D8,Pipe!$G:$G,Originadores!F$3) -> 0 | G8: =COUNTIFS(Pipe!$H:$H,Originadores!$D8,Pipe!$G:$G,Originadores!G$3) -> 0 | H8: =COUNTIFS(Pipe!$H:$H,Originadores!$D8,Pipe!$G:$G,Originadores!H$3) -> 1
C9: =+C8+1 -> 6 | D9: AGI | E9: Consultoria | F9: =COUNTIFS(Pipe!$H:$H,Originadores!$D9,Pipe!$G:$G,Originadores!F$3) -> 0 | G9: =COUNTIFS(Pipe!$H:$H,Originadores!$D9,Pipe!$G:$G,Originadores!G$3) -> 2 | H9: =COUNTIFS(Pipe!$H:$H,Originadores!$D9,Pipe!$G:$G,Originadores!H$3) -> 0
C10: =+C9+1 -> 7 | D10: Alex Giglio | E10: Broker | F10: =COUNTIFS(Pipe!$H:$H,Originadores!$D10,Pipe!$G:$G,Originadores!F$3) -> 1 | G10: =COUNTIFS(Pipe!$H:$H,Originadores!$D10,Pipe!$G:$G,Originadores!G$3) -> 2 | H10: =COUNTIFS(Pipe!$H:$H,Originadores!$D10,Pipe!$G:$G,Originadores!H$3) -> 4
C11: =+C10+1 -> 8 | D11: Allievo | E11: Acionista | F11: =COUNTIFS(Pipe!$H:$H,Originadores!$D11,Pipe!$G:$G,Originadores!F$3) -> 0 | G11: =COUNTIFS(Pipe!$H:$H,Originadores!$D11,Pipe!$G:$G,Originadores!G$3) -> 3 | H11: =COUNTIFS(Pipe!$H:$H,Originadores!$D11,Pipe!$G:$G,Originadores!H$3) -> 0
C12: =+C11+1 -> 9 | D12: Alvarez & Marsal | E12: Consultoria | F12: =COUNTIFS(Pipe!$H:$H,Originadores!$D12,Pipe!$G:$G,Originadores!F$3) -> 9 | G12: =COUNTIFS(Pipe!$H:$H,Originadores!$D12,Pipe!$G:$G,Originadores!G$3) -> 10 | H12: =COUNTIFS(Pipe!$H:$H,Originadores!$D12,Pipe!$G:$G,Originadores!H$3) -> 4
C13: =+C12+1 -> 10 | D13: Andreia Alonso | E13: Broker | F13: =COUNTIFS(Pipe!$H:$H,Originadores!$D13,Pipe!$G:$G,Originadores!F$3) -> 1 | G13: =COUNTIFS(Pipe!$H:$H,Originadores!$D13,Pipe!$G:$G,Originadores!G$3) -> 0 | H13: =COUNTIFS(Pipe!$H:$H,Originadores!$D13,Pipe!$G:$G,Originadores!H$3) -> 0
C14: =+C13+1 -> 11 | D14: ANTONIO CARLOS AMORIM Advogados | E14: Advogado | F14: =COUNTIFS(Pipe!$H:$H,Originadores!$D14,Pipe!$G:$G,Originadores!F$3) -> 0 | G14: =COUNTIFS(Pipe!$H:$H,Originadores!$D14,Pipe!$G:$G,Originadores!G$3) -> 1 | H14: =COUNTIFS(Pipe!$H:$H,Originadores!$D14,Pipe!$G:$G,Originadores!H$3) -> 0
C15: =+C14+1 -> 12 | D15: Antonio Lacombe | E15: Empresário / Executivo | F15: =COUNTIFS(Pipe!$H:$H,Originadores!$D15,Pipe!$G:$G,Originadores!F$3) -> 1 | G15: =COUNTIFS(Pipe!$H:$H,Originadores!$D15,Pipe!$G:$G,Originadores!G$3) -> 0 | H15: =COUNTIFS(Pipe!$H:$H,Originadores!$D15,Pipe!$G:$G,Originadores!H$3) -> 1
C16: =+C15+1 -> 13 | D16: Antonio Marques (Refix) | E16: Broker | F16: =COUNTIFS(Pipe!$H:$H,Originadores!$D16,Pipe!$G:$G,Originadores!F$3) -> 0 | G16: =COUNTIFS(Pipe!$H:$H,Originadores!$D16,Pipe!$G:$G,Originadores!G$3) -> 1 | H16: =COUNTIFS(Pipe!$H:$H,Originadores!$D16,Pipe!$G:$G,Originadores!H$3) -> 0
... C26: =+C25+1 -> 23 | D26: Banco Santos | E26: Banco | F26: =COUNTIFS(Pipe!$H:$H,Originadores!$D26,Pipe!$G:$G,Originadores!F$3) -> 0 | G26: =COUNTIFS(Pipe!$H:$H,Originadores!$D26,Pipe!$G:$G,Originadores!G$3) -> 1 | H26: =COUNTIFS(Pipe!$H:$H,Originadores!$D26,Pipe!$G:$G,Originadores!H$3) -> 0
C27: =+C26+1 -> 24 | D27: Banco Votorantim | E27: Banco
C28: =+C27+1 -> 25 | D28: Barbara Cibele | E28: Empresário / Executivo | F28: =COUNTIFS(Pipe!$H:$H,Originadores!$D28,Pipe!$G:$G,Originadores!F$3) -> 0 | G28: =COUNTIFS(Pipe!$H:$H,Originadores!$D28,Pipe!$G:$G,Originadores!G$3) -> 1 | H28: =COUNTIFS(Pipe!$H:$H,Originadores!$D28,Pipe!$G:$G,Originadores!H$3) -> 0
C29: =+C28+1 -> 26 | D29: BB Asset | E29: Asset | F29: =COUNTIFS(Pipe!$H:$H,Originadores!$D29,Pipe!$G:$G,Originadores!F$3) -> 1 | G29: =COUNTIFS(Pipe!$H:$H,Originadores!$D29,Pipe!$G:$G,Originadores!G$3) -> 0 | H29: =COUNTIFS(Pipe!$H:$H,Originadores!$D29,Pipe!$G:$G,Originadores!H$3) -> 0
C30: =+C29+1 -> 27 | D30: Bocom BBM | E30: Banco | F30: =COUNTIFS(Pipe!$H:$H,Originadores!$D30,Pipe!$G:$G,Originadores!F$3) -> 0 | G30: =COUNTIFS(Pipe!$H:$H,Originadores!$D30,Pipe!$G:$G,Originadores!G$3) -> 0 | H30: =COUNTIFS(Pipe!$H:$H,Originadores!$D30,Pipe!$G:$G,Originadores!H$3) -> 1
C31: =+C30+1 -> 28 | D31: Beam Capital / Almeida Mota | E31: Broker | F31: =COUNTIFS(Pipe!$H:$H,Originadores!$D31,Pipe!$G:$G,Originadores!F$3) -> 0 | G31: =COUNTIFS(Pipe!$H:$H,Originadores!$D31,Pipe!$G:$G,Originadores!G$3) -> 0 | H31: =COUNTIFS(Pipe!$H:$H,Originadores!$D31,Pipe!$G:$G,Originadores!H$3) -> 3
C32: =+C31+1 -> 29 | D32: BeeCap | E32: Asset | F32: =COUNTIFS(Pipe!$H:$H,Originadores!$D32,Pipe!$G:$G,Originadores!F$3) -> 1 | G32: =COUNTIFS(Pipe!$H:$H,Originadores!$D32,Pipe!$G:$G,Originadores!G$3) -> 0 | H32: =COUNTIFS(Pipe!$H:$H,Originadores!$D32,Pipe!$G:$G,Originadores!H$3) -> 0
C33: =+C32+1 -> 30 | D33: BF Capital | E33: Broker | F33: =COUNTIFS(Pipe!$H:$H,Originadores!$D33,Pipe!$G:$G,Originadores!F$3) -> 0 | G33: =COUNTIFS(Pipe!$H:$H,Originadores!$D33,Pipe!$G:$G,Originadores!G$3) -> 0 | H33: =COUNTIFS(Pipe!$H:$H,Originadores!$D33,Pipe!$G:$G,Originadores!H$3) -> 1
C34: =+C33+1 -> 31 | D34: BFMB Partners | E34: Broker | F34: =COUNTIFS(Pipe!$H:$H,Originadores!$D34,Pipe!$G:$G,Originadores!F$3) -> 0 | G34: =COUNTIFS(Pipe!$H:$H,Originadores!$D34,Pipe!$G:$G,Originadores!G$3) -> 0 | H34: =COUNTIFS(Pipe!$H:$H,Originadores!$D34,Pipe!$G:$G,Originadores!H$3) -> 2
C35: =+C34+1 -> 32 | D35: BGF Capital | E35: Broker | F35: =COUNTIFS(Pipe!$H:$H,Originadores!$D35,Pipe!$G:$G,Originadores!F$3) -> 0 | G35: =COUNTIFS(Pipe!$H:$H,Originadores!$D35,Pipe!$G:$G,Originadores!G$3) -> 2 | H35: =COUNTIFS(Pipe!$H:$H,Originadores!$D35,Pipe!$G:$G,Originadores!H$3) -> 0
C36: =+C35+1 -> 33 | D36: BlueOak | E36: Asset | F36: =COUNTIFS(Pipe!$H:$H,Originadores!$D36,Pipe!$G:$G,Originadores!F$3) -> 1 | G36: =COUNTIFS(Pipe!$H:$H,Originadores!$D36,Pipe!$G:$G,Originadores!G$3) -> 0 | H36: =COUNTIFS(Pipe!$H:$H,Originadores!$D36,Pipe!$G:$G,Originadores!H$3) -> 0
C37: =+C36+1 -> 34 | D37: BNDES | E37: BNDES | F37: =COUNTIFS(Pipe!$H:$H,Originadores!$D37,Pipe!$G:$G,Originadores!F$3) -> 0 | G37: =COUNTIFS(Pipe!$H:$H,Originadores!$D37,Pipe!$G:$G,Originadores!G$3) -> 1 | H37: =COUNTIFS(Pipe!$H:$H,Originadores!$D37,Pipe!$G:$G,Originadores!H$3) -> 1
C38: =+C37+1 -> 35 | D38: Bruno Advogado | E38: Advogado | F38: =COUNTIFS(Pipe!$H:$H,Originadores!$D38,Pipe!$G:$G,Originadores!F$3) -> 0 | G38: =COUNTIFS(Pipe!$H:$H,Originadores!$D38,Pipe!$G:$G,Originadores!G$3) -> 1 | H38: =COUNTIFS(Pipe!$H:$H,Originadores!$D38,Pipe!$G:$G,Originadores!H$3) -> 0
C39: =+C38+1 -> 36 | D39: Bruno Ribeiro | E39: Broker | F39: =COUNTIFS(Pipe!$H:$H,Originadores!$D39,Pipe!$G:$G,Originadores!F$3) -> 4 | G39: =COUNTIFS(Pipe!$H:$H,Originadores!$D39,Pipe!$G:$G,Originadores!G$3) -> 0 | H39: =COUNTIFS(Pipe!$H:$H,Originadores!$D39,Pipe!$G:$G,Originadores!H$3) -> 0
C40: =+C39+1 -> 37 | D40: Bruno Sotter | E40: Consultoria | F40: =COUNTIFS(Pipe!$H:$H,Originadores!$D40,Pipe!$G:$G,Originadores!F$3) -> 0 | G40: =COUNTIFS(Pipe!$H:$H,Originadores!$D40,Pipe!$G:$G,Originadores!G$3) -> 0 | H40: =COUNTIFS(Pipe!$H:$H,Originadores!$D40,Pipe!$G:$G,Originadores!H$3) -> 0
C41: =+C40+1 -> 38 | D41: BTG | E41: Banco
C42: =+C41+1 -> 39 | D42: BX Capital | E42: Consultoria | F42: =COUNTIFS(Pipe!$H:$H,Originadores!$D42,Pipe!$G:$G,Originadores!F$3) -> 1 | G42: =COUNTIFS(Pipe!$H:$H,Originadores!$D42,Pipe!$G:$G,Originadores!G$3) -> 0 | H42: =COUNTIFS(Pipe!$H:$H,Originadores!$D42,Pipe!$G:$G,Originadores!H$3) -> 0
C43: =+C42+1 -> 40 | D43: Caique Melo / Aventos | E43: Empresário / Executivo | F43: =COUNTIFS(Pipe!$H:$H,Originadores!$D43,Pipe!$G:$G,Originadores!F$3) -> 1 | G43: =COUNTIFS(Pipe!$H:$H,Originadores!$D43,Pipe!$G:$G,Originadores!G$3) -> 0 | H43: =COUNTIFS(Pipe!$H:$H,Originadores!$D43,Pipe!$G:$G,Originadores!H$3) -> 0
C44: =+C43+1 -> 41 | D44: Captal - Bruno Bianchesi | E44: Broker | F44: =COUNTIFS(Pipe!$H:$H,Originadores!$D44,Pipe!$G:$G,Originadores!F$3) -> 0 | G44: =COUNTIFS(Pipe!$H:$H,Originadores!$D44,Pipe!$G:$G,Originadores!G$3) -> 1 | H44: =COUNTIFS(Pipe!$H:$H,Originadores!$D44,Pipe!$G:$G,Originadores!H$3) -> 0
C45: =+C44+1 -> 42 | D45: Carlos Coelho | E45: Broker | F45: =COUNTIFS(Pipe!$H:$H,Originadores!$D45,Pipe!$G:$G,Originadores!F$3) -> 0 | G45: =COUNTIFS(Pipe!$H:$H,Originadores!$D45,Pipe!$G:$G,Originadores!G$3) -> 0 | H45: =COUNTIFS(Pipe!$H:$H,Originadores!$D45,Pipe!$G:$G,Originadores!H$3) -> 2
C46: =+C45+1 -> 43 | D46: Carlos Libera | E46: Empresário / Executivo | F46: =COUNTIFS(Pipe!$H:$H,Originadores!$D46,Pipe!$G:$G,Originadores!F$3) -> 1 | G46: =COUNTIFS(Pipe!$H:$H,Originadores!$D46,Pipe!$G:$G,Originadores!G$3) -> 0 | H46: =COUNTIFS(Pipe!$H:$H,Originadores!$D46,Pipe!$G:$G,Originadores!H$3) -> 0
C47: =+C46+1 -> 44 | D47: Carlos Simão | E47: Empresário / Executivo | F47: =COUNTIFS(Pipe!$H:$H,Originadores!$D47,Pipe!$G:$G,Originadores!F$3) -> 0 | G47: =COUNTIFS(Pipe!$H:$H,Originadores!$D47,Pipe!$G:$G,Originadores!G$3) -> 1 | H47: =COUNTIFS(Pipe!$H:$H,Originadores!$D47,Pipe!$G:$G,Originadores!H$3) -> 0
C48: =+C47+1 -> 45 | D48: Castro Barros | E48: Advogado | F48: =COUNTIFS(Pipe!$H:$H,Originadores!$D48,Pipe!$G:$G,Originadores!F$3) -> 0 | G48: =COUNTIFS(Pipe!$H:$H,Originadores!$D48,Pipe!$G:$G,Originadores!G$3) -> 4 | H48: =COUNTIFS(Pipe!$H:$H,Originadores!$D48,Pipe!$G:$G,Originadores!H$3) -> 0
C49: =+C48+1 -> 46 | D49: Castro e Silva | E49: Advogado | F49: =COUNTIFS(Pipe!$H:$H,Originadores!$D49,Pipe!$G:$G,Originadores!F$3) -> 0 | G49: =COUNTIFS(Pipe!$H:$H,Originadores!$D49,Pipe!$G:$G,Originadores!G$3) -> 1 | H49: =COUNTIFS(Pipe!$H:$H,Originadores!$D49,Pipe!$G:$G,Originadores!H$3) -> 0
C50: =+C49+1 -> 47 | D50: Cartesia Investimentos | E50: Asset | F50: =COUNTIFS(Pipe!$H:$H,Originadores!$D50,Pipe!$G:$G,Originadores!F$3) -> 0 | G50: =COUNTIFS(Pipe!$H:$H,Originadores!$D50,Pipe!$G:$G,Originadores!G$3) -> 0 | H50: =COUNTIFS(Pipe!$H:$H,Originadores!$D50,Pipe!$G:$G,Originadores!H$3) -> 1
...

Sheet Analise Originação 2025
C2: 2024 | D2: 2025 | K2: Tipo de Operação | L2: Nome | M2: Data Entrada | N2: a | O2: a | P2: a | Q2: De Para | Z2: > Infos Auxiliares | AD2: > Gráfico
B3: Casos Recebidos | C3: 260 | D3: =+COUNTIF(N:N,"2025") -> 372 | K3: Crédito | L3: Minter | M3: 45663 | N3: =YEAR(M3) -> 2025 | O3: JGP FA | P3: Advisor | Q3: =+INDEX($AA$3:$AA$19,MATCH(P3,$Z$3:$Z$19,0)) -> Consultoria | U3: Consultoria | V3: =COUNTIF($Q$3:$Q$374,U3) -> 132 | W3: =+V3/$V$10 -> 0.35483871 | Z3: Advisor | AA3: Consultoria | AD3: Consultoria | AE3: =+W3 -> 0.35483871 | AK3: JGP FA
B4: Casos Pre analisados | C4: 90 | D4: =+$D$3*E4 -> 128.76923 | E4: =+C4/$C$3 -> 0.34615385 | K4: Crédito RJ | L4: Portal Agro | M4: 45663 | N4: =YEAR(M4) -> 2025 | O4: X2W | P4: Advisor | Q4: =+INDEX($AA$3:$AA$19,MATCH(P4,$Z$3:$Z$19,0)) -> Consultoria | U4: Broker | V4: =COUNTIF($Q$3:$Q$374,U4) -> 114 | W4: =+V4/$V$10 -> 0.30645161 | Z4: Acionista | AA4: Empresários / Executivo | AD4: Broker | AE4: =+W4 -> 0.30645161 | AK4: X2W
B5: Casos Aprofundados | C5: 70 | D5: =+$D$3*E5 -> 100.15385 | E5: =+C5/$C$3 -> 0.26923077 | K5: Crédito RJ | L5: Hospital Lucio Rebelo | M5: 45663 | N5: =YEAR(M5) -> 2025 | O5: Dyamonte | P5: Advisor | Q5: =+INDEX($AA$3:$AA$19,MATCH(P5,$Z$3:$Z$19,0)) -> Consultoria | U5: Empresários / Executivo | V5: =COUNTIF($Q$3:$Q$374,U5) -> 33 | W5: =+V5/$V$10 -> 0.088709677 | Z5: Broker | AA5: Broker | AD5: Escritório Adv. | AE5: =+W8 -> 0.14247312 | AK5: Dyamonte
B6: Propostas Enviadas | C6: 15 | D6: =+$D$3*E6 -> 21.461538 | E6: =+C6/$C$3 -> 0.057692308 | K6: Crédito Estruturado | L6: Projesan | M6: 45663 | N6: =YEAR(M6) -> 2025 | O6: Heartman House | P6: Advisor | Q6: =+INDEX($AA$3:$AA$19,MATCH(P6,$Z$3:$Z$19,0)) -> Consultoria | U6: Outros | V6: =COUNTIF($Q$3:$Q$374,U6) -> 8 | W6: =+V6/$V$10 -> 0.021505376 | Z6: Advogado | AA6: Escritório Adv. | AD6: Empresários / Executivo | AE6: =+W5 -> 0.088709677 | AK6: Heartman House
B7: Investimentos Realizados | C7: 9 | D7: 6 | E7: =+C7/$C$3 -> 0.034615385 | F7: =+D7/D3 -> 0.016129032 | K7: Precatorio Estadual | L7: Precatório de Fortaleza | M7: 45670 | N7: =YEAR(M7) -> 2025 | O7: Enio | P7: Broker | Q7: =+INDEX($AA$3:$AA$19,MATCH(P7,$Z$3:$Z$19,0)) -> Broker | U7: Asset | V7: =COUNTIF($Q$3:$Q$374,U7) -> 17 | W7: =+V7/$V$10 -> 0.045698925 | Z7: Originação Própria | AA7: Originação Própria | AD7: Asset | AE7: =+W7 -> 0.045698925 | AK7: Aeté
K8: Crédito | L8: Blendpaper | M8: 45673 | N8: =YEAR(M8) -> 2025 | O8: JGP FA | P8: Advisor | Q8: =+INDEX($AA$3:$AA$19,MATCH(P8,$Z$3:$Z$19,0)) -> Consultoria | U8: Escritório Adv. | V8: =COUNTIF($Q$3:$Q$374,U8) -> 53 | W8: =+V8/$V$10 -> 0.14247312 | Z8: Banco | AA8: Banco | AD8: Banco | AE8: =+W9 -> 0.040322581 | AK8: Alvarez & Marsal
K9: Precatório Federal | L9: Caixa Prev | M9: 45674 | N9: =YEAR(M9) -> 2025 | O9: JGP FA | P9: Advisor | Q9: =+INDEX($AA$3:$AA$19,MATCH(P9,$Z$3:$Z$19,0)) -> Consultoria | U9: Banco | V9: =COUNTIF($Q$3:$Q$374,U9) -> 15 | W9: =+V9/$V$10 -> 0.040322581 | Z9: Gestora | AA9: Asset | AD9: Outros | AE9: =+W6 -> 0.021505376 | AK9: Renato Gorni - RMR Corporate
K10: Direito Creditórios | L10: Jari Celulose | M10: 45674 | N10: =YEAR(M10) -> 2025 | O10: Aeté | P10: Advisor | Q10: =+INDEX($AA$3:$AA$19,MATCH(P10,$Z$3:$Z$19,0)) -> Consultoria | U10: Total | V10: =+SUM(V3:V9) -> 372 | Z10: Empresário / Executivo | AA10: Empresários / Executivo | AK10: Stark Investment Banking
K11: Crédito Estruturado | L11: Bravante | M11: 45674 | N11: =YEAR(M11) -> 2025 | O11: Alvarez & Marsal | P11: Advisor | Q11: =+INDEX($AA$3:$AA$19,MATCH(P11,$Z$3:$Z$19,0)) -> Consultoria | Z11: Boutique | AA11: Consultoria | AK11: IFINC
K12: Crédito Estruturado | L12: Superfrio | M12: 45674 | N12: =YEAR(M12) -> 2025 | O12: Alvarez & Marsal | P12: Advisor | Q12: =+INDEX($AA$3:$AA$19,MATCH(P12,$Z$3:$Z$19,0)) -> Consultoria | Z12: Consultoria | AA12: Consultoria | AK12: Penaforte
K13: Crédito | L13: Allievo | M13: 45674 | N13: =YEAR(M13) -> 2025 | O13: Allievo | P13: Acionista | Q13: =+INDEX($AA$3:$AA$19,MATCH(P13,$Z$3:$Z$19,0)) -> Empresários / Executivo | Z13: JGP FA | AA13: Consultoria | AK13: Rio Investimentos
K14: Precatório Municipal | L14: Formosa | M14: 45674 | N14: =YEAR(M14) -> 2025 | O14: Renato Gorni - RMR Corporate | P14: Advisor | Q14: =+INDEX($AA$3:$AA$19,MATCH(P14,$Z$3:$Z$19,0)) -> Consultoria | Z14: Asset | AA14: Asset | AK14: Franklin Templaton
K15: Crédito Estruturado | L15: Itagres | M15: 45680 | N15: =YEAR(M15) -> 2025 | O15: Stark Investment Banking | P15: Advisor | Q15: =+INDEX($AA$3:$AA$19,MATCH(P15,$Z$3:$Z$19,0)) -> Consultoria | Z15: Empresário/Executivo | AA15: Empresários / Executivo | AK15: RFA
K16: Crédito | L16: Serra Azul | M16: 45680 | N16: =YEAR(M16) -> 2025 | O16: Stark Investment Banking | P16: Advisor | Q16: =+INDEX($AA$3:$AA$19,MATCH(P16,$Z$3:$Z$19,0)) -> Consultoria | Z16: Executivo/empresário | AA16: Empresários / Executivo | AK16: FTI
K17: Crédito | L17: Conduzvale | M17: 45680 | N17: =YEAR(M17) -> 2025 | O17: Stark Investment Banking | P17: Advisor | Q17: =+INDEX($AA$3:$AA$19,MATCH(P17,$Z$3:$Z$19,0)) -> Consultoria | Z17: Executivo | AA17: Empresários / Executivo | AK17: Makalu
K18: Crédito | L18: Villa Lisboa | M18: 45680 | N18: =YEAR(M18) -> 2025 | O18: Stark Investment Banking | P18: Advisor | Q18: =+INDEX($AA$3:$AA$19,MATCH(P18,$Z$3:$Z$19,0)) -> Consultoria | Z18: Fundo | AA18: Asset | AK18: CVPM
K19: Formulário de Referência/Leme Forense | M19: 45688 | N19: =YEAR(M19) -> 2025 | Q19: Outros | Z19: BNDES | AA19: Banco | AK19: Houlihan Lokey
K20: Crédito | L20: Ultracheese | M20: 45679 | N20: =YEAR(M20) -> 2025 | O20: Nippur | P20: Broker | Q20: =+INDEX($AA$3:$AA$19,MATCH(P20,$Z$3:$Z$19,0)) -> Broker | AK20: Jonatas Couri (EQI)
K21: Crédito | L21: Elisa Agro | M21: 45679 | N21: =YEAR(M21) -> 2025 | O21: Alvarez & Marsal | P21: Advisor | Q21: =+INDEX($AA$3:$AA$19,MATCH(P21,$Z$3:$Z$19,0)) -> Consultoria | AK21: Troesser
K22: Precatório Federal | L22: Frango Norte | M22: 45679 | N22: =YEAR(M22) -> 2025 | O22: Renato Gorni - RMR Corporate | P22: Broker | Q22: =+INDEX($AA$3:$AA$19,MATCH(P22,$Z$3:$Z$19,0)) -> Broker | AK22: Laplace
K23: Precatório Federal | L23: Precatorio Santa Cruz | M23: 45679 | N23: =YEAR(M23) -> 2025 | O23: Connectas Capital | P23: Broker | Q23: =+INDEX($AA$3:$AA$19,MATCH(P23,$Z$3:$Z$19,0)) -> Broker
K24: SITE RI | M24: 45688 | N24: =YEAR(M24) -> 2025 | O24: PAGOOS | Q24: Broker
K25: Crédito | L25: Construtora OAB | M25: 45679 | N25: =YEAR(M25) -> 2025 | O25: Stark Investment Banking | P25: Advisor | Q25: =+INDEX($AA$3:$AA$19,MATCH(P25,$Z$3:$Z$19,0)) -> Consultoria | AK25: Triunfae
K26: Crédito Trabalhista | L26: Galileu e Assespa | M26: 45684 | N26: =YEAR(M26) -> 2025 | O26: Alvarez & Marsal | P26: Advisor | Q26: =+INDEX($AA$3:$AA$19,MATCH(P26,$Z$3:$Z$19,0)) -> Consultoria | AK26: Zera.AG
K27: Pré-Precatório Federal | L27: Aspometron | M27: 45684 | N27: =YEAR(M27) -> 2025 | O27: Empresário | P27: Empresário / Executivo | Q27: =+INDEX($AA$3:$AA$19,MATCH(P27,$Z$3:$Z$19,0)) -> Empresários / Executivo
K28: Crédito | L28: Fribarreiras | M28: 45684 | N28: =YEAR(M28) -> 2025 | Q28: Consultoria | AK28: Integra Associados
K29: DIP | L29: Grupo Lagos de Itaipava | M29: 45687 | N29: =YEAR(M29) -> 2025 | O29: IFINC | P29: Advisor | Q29: =+INDEX($AA$3:$AA$19,MATCH(P29,$Z$3:$Z$19,0)) -> Consultoria | AK29: Ecowa
K30: Direito Creditórios | L30: São Paulo | M30: 45686 | N30: =YEAR(M30) -> 2025 | O30: Penaforte | P30: Advisor | Q30: =+INDEX($AA$3:$AA$19,MATCH(P30,$Z$3:$Z$19,0)) -> Consultoria | AK30: Dealmaker
K31: Direito Creditórios | L31: MRV | M31: 45686 | N31: =YEAR(M31) -> 2025 | O31: Penaforte | P31: Advisor | Q31: =+INDEX($AA$3:$AA$19,MATCH(P31,$Z$3:$Z$19,0)) -> Consultoria | AK31: Leandro Gomes (MA7)
K32: Precatório Estadual | L32: Precatórios do RN | M32: 45685 | N32: =YEAR(M32) -> 2025 | O32: Octo Capital | P32: Broker | Q32: =+INDEX($AA$3:$AA$19,MATCH(P32,$Z$3:$Z$19,0)) -> Broker
K33: Direitos Creditórios | L33: Coimex | M33: 45685 | N33: =YEAR(M33) -> 2025 | O33: Alvarez & Marsal | P33: Advisor | Q33: =+INDEX($AA$3:$AA$19,MATCH(P33,$Z$3:$Z$19,0)) -> Consultoria | AK33: Letro Consultoria
K34: Direitos Creditórios | L34: Construtora Moraes Sampaio | M34: 45685 | N34: =YEAR(M34) -> 2025 | O34: Rio Investimentos | P34: Advisor | Q34: =+INDEX($AA$3:$AA$19,MATCH(P34,$Z$3:$Z$19,0)) -> Consultoria | AK34: Hayden Capital
K35: Direitos Creditórios | L35: Condominio x Gafisa | M35: 45685 | N35: =YEAR(M35) -> 2025 | O35: Rio Investimentos | P35: Advisor | Q35: =+INDEX($AA$3:$AA$19,MATCH(P35,$Z$3:$Z$19,0)) -> Consultoria | AK35: AGI
K36: Precatório Federal | L36: Clinica Reviver | M36: 45685 | N36: =YEAR(M36) -> 2025 | O36: Nippur/FA | P36: Broker | Q36: =+INDEX($AA$3:$AA$19,MATCH(P36,$Z$3:$Z$19,0)) -> Broker | AK36: FGA
K37: Precatório Federal | L37: Instituto de Saúde e Educação Vida | M37: 45685 | N37: =YEAR(M37) -> 2025 | O37: Nippur/FA | P37: Broker | Q37: =+INDEX($AA$3:$AA$19,MATCH(P37,$Z$3:$Z$19,0)) -> Broker
K38: Crédito Estruturado | L38: Aluguel de Freezer da Metalfrio | M38: 45686 | N38: =YEAR(M38) -> 2025 | O38: Oriz | P38: Asset | Q38: =+INDEX($AA$3:$AA$19,MATCH(P38,$Z$3:$Z$19,0)) -> Asset
K39: Precatório Estadual | L39: Sealion | M39: 45685 | N39: =YEAR(M39) -> 2025 | O39: Marco Andre Alencar | P39: Broker | Q39: =+INDEX($AA$3:$AA$19,MATCH(P39,$Z$3:$Z$19,0)) -> Broker | AK39: Verdeau
K40: Precatório Estadual | L40: Precatório Ceará (Marleiba) | M40: 45685 | N40: =YEAR(M40) -> 2025 | O40: Enio | P40: Broker | Q40: =+INDEX($AA$3:$AA$19,MATCH(P40,$Z$3:$Z$19,0)) -> Broker | AK40: RPC Par
K41: Precatório Estadual | L41: Precatório Bahia | M41: 45688 | N41: =YEAR(M41) -> 2025 | O41: Roberto Roland | P41: Broker | Q41: =+INDEX($AA$3:$AA$19,MATCH(P41,$Z$3:$Z$19,0)) -> Broker | AK41: Valuation Partners
...

Sheet Reestruturação
C2: Nome | D2: Responsável
C3: Allonda
C4: Skyfit
C5: Eveo | D5: Tirar
C6: Grupo Pakera | D6: Tirar
C7: GBS
C8: IUGU | D8: Tirar
C9: Projeto Nimbus | D9: Tirar e Sem espaço para empresa não auditada no book de HY
C10: Grupo Montes Belos | D10: Tirar
C11: Weclix
C12: Usina Ory (Etanol de Milho) | D12: Aprofundar
C13: Braskem | D13: mandar a reportagem
C14: Kimberlite | D14: Falar com Carlos Watanabe (Valuation)
C15: JFL Living
C16: BDG Incorporadora
C17: Cocelpa
C18: BRAM

Sheet Vertical_1812
D2: Casos analisados desde Outubro 2025
C3: # | D3: Ativos Financeiros | E3: Operação | F3: Setor | G3: Status | I3: Entraram | J3: 24
C4: 1 | D4: JFL Living | E4: Crédito Estruturado | F4: Real Estate | G4: Aprovado em Comitê de High Yield | I4: Saídas Reunião Anterior | J4: 15
C5: =+C4+1 -> 2 | D5: Cocelpa | E5: Crédito Estruturado | F5: Papel e Celulose | G5: Proposta Indicativa enviada | I5: Novas Saídas | J5: 27
C6: =+C5+1 -> 3 | D6: Edital BNDES NPL | E6: NPL | F6: Banco | G6: Enviamos os documentos, aguardando resposta | I6: Numero da Lista Anterior | J6: 38
C7: =+C6+1 -> 4 | D7: Oxe Energia | E7: Crédito Estruturado | F7: Energia | G7: Em análise | I7: Casos Ativos | J7: =+J3-J4-J5+J6 -> 20
C8: =+C7+1 -> 5 | D8: Eletrodata | E8: DIP | F8: Engenharia | G8: Aguardando Informações do Modelo
C9: =+C8+1 -> 6 | D9: Carteira da Petrobras - NPL | E9: NPL | F9: O&G | G9: Vamos enviar nossos dados
C10: =+C9+1 -> 7 | D10: Gás Verde | E10: Crédito Estruturado | F10: Energia | G10: Em análise para High Yield
C11: =+C10+1 -> 8 | D11: CI Banco | E11: Crédito Estruturado | F11: Financeiro | G11: Agendando reunião
C12: =+C11+1 -> 9 | D12: Familia Levinsohn - ITCMD | E12: Crédito Estruturado | F12: Agro | G12: Proposta indicativa enviada
C13: =+C12+1 -> 10 | D13: Grupo Nova Ebenézer | E13: NPL | F13: Agro | G13: Aguardando bancos para entender se tem negocio da venda dos creditos 30-35% par
C14: =+C13+1 -> 11 | D14: PDG | E14: NPL | F14: Real Estate | G14: Agendando reunião com a Companhia
C15: =+C14+1 -> 12 | D15: Casas Bahia | E15: Debenture | F15: Varejo | G15: Acompanhar a reestruturação das Casas Bahia - venda @22%PAR
C16: =+C15+1 -> 13 | D16: BJ Grupo | E16: DIP | F16: Combustível | G16: Aguardando informações
C17: =+C16+1 -> 14 | D17: Sencinet | E17: DIP | F17: Tecnologia | G17: Aguardando informações
C18: =+C17+1 -> 15 | D18: Kozma x Campina | E18: NPL | G18: Em análise
C19: =+C18+1 -> 16 | D19: Mave | E19: Crédito Estruturado | F19: Varejo | G19: Em análise
C20: =+C19+1 -> 17 | D20: Sanes | E20: Crédito Estruturado | F20: Alimentos | G20: Em análise
C21: =+C20+1 -> 18 | D21: Enseada | E21: DIP/NPL | F21: Navegação | G21: Em análise
C22: =+C21+1 -> 19 | D22: Allonda | E22: DIP/NPL | F22: Engenharia | G22: G5 em negociação com BOFA
C23: =+C22+1 -> 20 | D23: BRAX | E23: Crédito Estruturado | F23: Esporte | G23: NDA pendente de assinatura
C24: =+C23+1 -> 21 | D24: Dessana Emerald | E24: Crédito Estruturado | F24: Mineração | G24: Operação sem fit com o fundo
C25: =+C24+1 -> 22 | D25: Produza | E25: Crédito Estruturado | F25: Industria | G25: Ramp-up operacional robusto e pouca garantia
C26: =+C25+1 -> 23 | D26: Figueirense | E26: DIP | F26: Esporte | G26: Julgamento de agravos e potencial garantia ainda travada
C27: =+C26+1 -> 24 | D27: Skyfit | E27: Crédito Estruturado | F27: Academia | G27: Spread da proposta distante da nossa taxa
C28: =+C27+1 -> 25 | D28: Usina Ory (Etanol de Milho) | E28: Crédito Estruturado | F28: Energia | G28: Poucas garantias
C29: =+C28+1 -> 26 | D29: Instituiçao SP x Cyrela | E29: Crédito Estruturado | F29: Construção | G29: Sem aprovação da capacidade de pagamento
C30: =+C29+1 -> 27 | D30: Papelex | E30: DIP | F30: Varejo | G30: RJ com poucas garantias
... C50: =+C49+1 -> 47 | D50: Empresa de Cerâmica (Artec) | E50: DIP | F50: Agro | G50: Ativo operacional em garantia
C55: # | D55: Ativos Judiciais | E55: Operação | F55: Status
C56: 1 | D56: Valmont x Pivo | E56: Legal Claim | F56: Em análise, vamos precificar
C57: =+C56+1 -> 2 | D57: Crefisa | E57: Legal Claim | F57: Aguardando reunião com o Serrano
C58: =+C57+1 -> 3 | D58: Incobrasa | E58: Legal Claim | F58: Em análise
C59: =+C58+1 -> 4 | D59: Unipar x Petrobras | E59: Legal Claim | F59: Estão verificando o entendimento da Selic
C60: =+C59+1 -> 5 | D60: Créditos ODB - VLT | E60: Precatório Municipal | F60: Em análise
C61: =+C60+1 -> 6 | D61: Difal Elfa | E61: Legal Claim | F61: Em análise
C62: =+C61+1 -> 7 | D62: Zemax | E62: Pré Precatório Federal | F62: Analisando o envio da proposta
C63: =+C62+1 -> 8 | D63: Full Comex Trading x União | E63: Pré Precatório Federal | F63: Em análise
C64: =+C63+1 -> 9 | D64: Carteira de Precatórios - Estre Ambiental | E64: Precatório | F64: Em análise
...

Sheet Vertical_1610
D2: Casos analisados desde Setembro 2025
C3: # | D3: Ativos Financeiros | E3: Operação | F3: Setor | G3: Status | I3: Entraram | J3: 16 | N3: # | O3: Ativos Financeiros | P3: Operação | Q3: Setor | R3: Status
C4: 1 | D4: Braskem | E4: Debenture | F4: Industria | G4: Concluído. Investimos R$ 2.6m (2% do fundo) @37%PAR | I4: Saídas Reunião Anterior | J4: 17 | N4: 1 | O4: Braskem | P4: Debenture | Q4: Industria | R4: Concluído. Investimos R$ 2.6m (2% do fundo) @37%PAR | S4: =+INDEX(Pipe!N:N,MATCH(O4,Pipe!E:E,0)) -> Concluído
C5: =+C4+1 -> 2 | D5: Familia Levinsohn - ITCMD | E5: Crédito Estruturado | F5: Agro | G5: Proposta indicativa enviada | I5: Novas Saídas | J5: 2 | N5: =+N4+1 -> 2 | O5: Familia Levinsohn - ITCMD | P5: Crédito Estruturado | Q5: Agro | R5: Proposta indicativa enviada | S5: =+INDEX(Pipe!N:N,MATCH(O5,Pipe!E:E,0)) -> #N/A
C6: =+C5+1 -> 3 | D6: Instituiçao SP x Cyrela | E6: Crédito Estruturado | F6: Construção | G6: Proposta enviada | I6: Numero da Lista Anterior | J6: 40 | N6: =+N5+1 -> 3 | O6: Instituiçao SP x Cyrela | P6: Crédito Estruturado | Q6: Construção | R6: Proposta enviada | S6: =+INDEX(Pipe!N:N,MATCH(O6,Pipe!E:E,0)) -> #N/A
C7: =+C6+1 -> 4 | D7: Allonda | E7: DIP/NPL | F7: Engenharia | G7: Estamos preparando proposta indicativa | I7: Casos Ativos | J7: =+J3-J4-J5+J6 -> 37 | N7: =+N6+1 -> 4 | O7: Allonda | P7: DIP/NPL | Q7: Engenharia | R7: Estamos preparando proposta indicativa
C8: =+C7+1 -> 5 | D8: Cocelpa | E8: Crédito Estruturado | F8: Papel e Celulose | G8: Estamos preparando proposta indicativa | N8: =+N7+1 -> 5 | O8: Cocelpa | P8: Crédito Estruturado | Q8: Papel e Celulose | R8: Estamos preparando proposta indicativa
C9: =+C8+1 -> 6 | D9: Papelex | E9: DIP | F9: Varejo | G9: Em análise
C10: =+C9+1 -> 7 | D10: Elba Equipamentos e Serviços | E10: Crédito Estruturado | F10: Aluguel de Equipamentos | G10: Em análise
C11: =+C10+1 -> 8 | D11: Valetão Pneus | E11: DIP/NPL | F11: Varejo | G11: Pendente do envio de informações | N11: =+N8+1 -> 6 | O11: Valetão Pneus | P11: DIP/NPL | Q11: Varejo | R11: Pendente do envio de informações | S11: =+INDEX(Pipe!N:N,MATCH(O11,Pipe!E:E,0)) -> Não
C12: =+C11+1 -> 9 | D12: Cara Preta | E12: Crédito Estruturado | F12: Agro | G12: Pendente de resposta da EQI sobre a distribuição do fundo | I12: meza 20% a.a + 20% kicker | N12: =+N11+1 -> 7 | O12: Cara Preta | P12: Crédito Estruturado | Q12: Agro | R12: Pendente de resposta da EQI sobre a distribuição do fundo | S12: =+INDEX(Pipe!N:N,MATCH(O12,Pipe!E:E,0)) -> Não
C13: =+C12+1 -> 10 | D13: Grupo DTW | F13: Agro
C14: =+C13+1 -> 11
C15: =+C14+1 -> 12 | D15: Usina Ory (Etanol de Milho) | E15: Crédito Estruturado | F15: Energia | G15: Em análise
C16: =+C15+1 -> 13 | D16: Sanes | E16: Crédito Estruturado | F16: Alimentos | G16: Aguardando Informação
C17: =+C16+1 -> 14 | D17: Enseada | E17: DIP/NPL | F17: Navegação | G17: Aguardando Informações
C18: =+C17+1 -> 15 | D18: Tinguá | E18: Crédito Estruturado | F18: Transportes | G18: Em análise
C19: =+C18+1 -> 16 | D19: Cremona Capital | E19: Crédito Estruturado | F19: Consórcio | G19: Entendendo o background dos originadores | N19: =+N12+1 -> 8 | O19: Tinguá | P19: Crédito Estruturado | Q19: Transportes | R19: Em análise | S19: =+INDEX(Pipe!N:N,MATCH(O19,Pipe!E:E,0)) -> Não
C20: =+C19+1 -> 17 | D20: Figueirense | E20: DIP | F20: Esporte | G20: Em análise da RJ | N20: =+N19+1 -> 9 | O20: Cremona Capital | P20: Crédito Estruturado | Q20: Consórcio | R20: Entendendo o background dos originadores | S20: =+INDEX(Pipe!N:N,MATCH(O20,Pipe!E:E,0)) -> Não
C21: =+C20+1 -> 18 | D21: Eletrodata | E21: DIP | F21: Engenharia | G21: Aguardando Informações do Fluxo de Pagamento do DIP | N21: =+N20+1 -> 10 | O21: Figueirense | P21: DIP | Q21: Esporte | R21: Em análise da RJ
C22: =+C21+1 -> 19 | D22: JFL Living | E22: Crédito Estruturado | F22: Real Estate | G22: Operação enviada para High Yield | N22: =+N21+1 -> 11 | O22: Eletrodata | P22: DIP | Q22: Engenharia | R22: Aguardando Informações do Fluxo de Pagamento do DIP | S22: =+INDEX(Pipe!N:N,MATCH(O22,Pipe!E:E,0)) -> Não
C23: =+C22+1 -> 20 | D23: Skyfit | E23: Crédito Estruturado | F23: Academia | G23: Aguardando informações do VDR | N23: =+N22+1 -> 12 | O23: Skyfit | P23: Crédito Estruturado | Q23: Academia | R23: Aguardando informações do VDR | S23: =+INDEX(Pipe!N:N,MATCH(O23,Pipe!E:E,0)) -> Não
C24: =+C23+1 -> 21 | D24: GBS | E24: Crédito Estruturado | F24: Energia | G24: Em análise | N24: =+N23+1 -> 13 | O24: JFL Living | P24: Crédito Estruturado | Q24: Real Estate | R24: Operação enviada para High Yield | S24: =+INDEX(Pipe!N:N,MATCH(O24,Pipe!E:E,0)) -> Não
C25: =+C24+1 -> 22 | D25: Marabraz | E25: Crédito Estruturado | F25: Varejo | G25: Aguardando nova reuniao | N25: =+N24+1 -> 14 | O25: GBS | P25: Crédito Estruturado | Q25: Energia | R25: Em análise | S25: =+INDEX(Pipe!N:N,MATCH(O25,Pipe!E:E,0)) -> Não
C26: =+C25+1 -> 23 | D26: Weclix | E26: NPL | F26: Fibra Óptica | G26: Aguardando envio de informações | N26: =+N25+1 -> 15 | O26: Marabraz | P26: Crédito Estruturado | Q26: Varejo | R26: Aguardando nova reuniao | S26: =+INDEX(Pipe!N:N,MATCH(O26,Pipe!E:E,0)) -> On Hold
C27: =+C26+1 -> 24 | D27: BRAX | E27: Crédito Estruturado | F27: Esporte | G27: NDA pendente de assinatura | N27: =+N26+1 -> 16 | O27: Weclix | P27: NPL | Q27: Fibra Óptica | R27: Aguardando envio de informações | S27: =+INDEX(Pipe!N:N,MATCH(O27,Pipe!E:E,0)) -> Não
C28: =+C27+1 -> 25 | D28: Mineração Dagoberto | E28: Crédito Estruturado | F28: Mineração | G28: Aguardando resolução da transação tributária | N28: =+N27+1 -> 17 | O28: BRAX | P28: Crédito Estruturado | Q28: Esporte | R28: NDA pendente de assinatura | S28: =+INDEX(Pipe!N:N,MATCH(O28,Pipe!E:E,0)) -> Não
C29: =+C28+1 -> 26 | D29: Lavoro | E29: Crédito Estruturado | F29: Agro | G29: Vão buscar outras formas de financiamento | N29: =+N28+1 -> 18 | O29: Mineração Dagoberto | P29: Crédito Estruturado | Q29: Mineração | R29: Aguardando resolução da transação tributária | S29: =+INDEX(Pipe!N:N,MATCH(O29,Pipe!E:E,0)) -> On Hold
C30: =+C29+1 -> 27 | D30: EMAE | E30: Crédito Estruturado | F30: Energia | G30: Garantias de Tenure, Tercio e Ambipar | N30: =+N29+1 -> 19 | O30: Lavoro | P30: Crédito Estruturado | Q30: Agro | R30: Vão buscar outras formas de financiamento | S30: =+INDEX(Pipe!N:N,MATCH(O30,Pipe!E:E,0)) -> Não
C31: =+C30+1 -> 28 | D31: Kimberlite | E31: Crédito Estruturado | F31: Industria | G31: Operaçao sem fit com o fundo | N31: =+N30+1 -> 20 | O31: EMAE | P31: Crédito Estruturado | Q31: Energia | R31: Garantias de Tenure, Tercio e Ambipar | S31: =+INDEX(Pipe!N:N,MATCH(O31,Pipe!E:E,0)) -> On Hold
C32: =+C31+1 -> 29 | D32: Metodista (Trabalhista) | E32: NPL | F32: Grupo de Ensino | G32: Aguardando Cia sobre renegociação de prazos do PRJ | N32: =+N31+1 -> 21 | O32: Kimberlite | P32: Crédito Estruturado | Q32: Industria | R32: Operaçao sem fit com o fundo | S32: =+INDEX(Pipe!N:N,MATCH(O32,Pipe!E:E,0)) -> Não
C33: =+C32+1 -> 30 | D33: Metodista (DIP) | E33: DIP | F33: Grupo de Ensino | G33: Aguardando Cia sobre renegociação de prazos do PRJ | N33: =+N32+1 -> 22 | O33: Metodista (Trabalhista) | P33: NPL | Q33: Grupo de Ensino | R33: Aguardando Cia sobre renegociação de prazos do PRJ | S33: =+INDEX(Pipe!N:N,MATCH(O33,Pipe!E:E,0)) -> Não
... C40: =+C39+1 -> 37 | D40: Riomar | E40: Crédito Estruturado | F40: Industria | G40: Nao tem imoveis que nao operacional pra colocar na operaçao | N40: =+N39+1 -> 29 | O40: BDG Incorporadora | P40: Crédito Estruturado | Q40: Incorporadora | R40: Baixo faturamento e financiamento de obra, garantia operacional | S40: =+INDEX(Pipe!N:N,MATCH(O40,Pipe!E:E,0)) -> Não
